Ignoring exception in command play:
Traceback (most recent call last):
  File "/home/pi/.local/lib/python3.7/site-packages/discord/ext/commands/bot.py", line 902, in invoke
    await ctx.command.invoke(ctx)
  File "/home/pi/.local/lib/python3.7/site-packages/discord/ext/commands/core.py", line 856, in invoke
    await self.prepare(ctx)
  File "/home/pi/.local/lib/python3.7/site-packages/discord/ext/commands/core.py", line 790, in prepare
    await self._parse_arguments(ctx)
  File "/home/pi/.local/lib/python3.7/site-packages/discord/ext/commands/core.py", line 697, in _parse_arguments
    transformed = await self.transform(ctx, param)
  File "/home/pi/.local/lib/python3.7/site-packages/discord/ext/commands/core.py", line 542, in transform
    raise MissingRequiredArgument(param)
discord.ext.commands.errors.MissingRequiredArgument: url is a required argument that is missing.
Ignoring exception in command None:
discord.ext.commands.errors.CommandNotFound: Command "warn" is not found
lancement du bot...
{'689549866774429734': 1, '700707495106052134': 1}
Ready
lancement du bot...
{'689549866774429734': 1, '700707495106052134': 1}
Ready
aucun warning
warning ajout√©: 689549866774429734 1 /3
